[2024-06-11T11:26:33.229+0000] {local_task_job_runner.py:120} INFO - ::group::Pre task execution logs
[2024-06-11T11:26:33.253+0000] {taskinstance.py:2076} INFO - Dependencies all met for dep_context=non-requeueable deps ti=<TaskInstance: trigger_dag_id.file_sensor manual__2024-06-11T11:26:23.981118+00:00 [queued]>
[2024-06-11T11:26:33.262+0000] {taskinstance.py:2076} INFO - Dependencies all met for dep_context=requeueable deps ti=<TaskInstance: trigger_dag_id.file_sensor manual__2024-06-11T11:26:23.981118+00:00 [queued]>
[2024-06-11T11:26:33.263+0000] {taskinstance.py:2306} INFO - Starting attempt 1 of 1
[2024-06-11T11:26:33.282+0000] {taskinstance.py:2330} INFO - Executing <Task(FileSensor): file_sensor> on 2024-06-11 11:26:23.981118+00:00
[2024-06-11T11:26:33.289+0000] {warnings.py:110} WARNING - /home/***/.local/lib/python3.12/site-packages/***/task/task_runner/standard_task_runner.py:61: DeprecationWarning: This process (pid=1177) is multi-threaded, use of fork() may lead to deadlocks in the child.
  pid = os.fork()

[2024-06-11T11:26:33.291+0000] {standard_task_runner.py:63} INFO - Started process 1179 to run task
[2024-06-11T11:26:33.291+0000] {standard_task_runner.py:90} INFO - Running: ['***', 'tasks', 'run', 'trigger_dag_id', 'file_sensor', 'manual__2024-06-11T11:26:23.981118+00:00', '--job-id', '765', '--raw', '--subdir', 'DAGS_FOLDER/trigger_dag.py', '--cfg-path', '/tmp/tmpggrm49lw']
[2024-06-11T11:26:33.293+0000] {standard_task_runner.py:91} INFO - Job 765: Subtask file_sensor
[2024-06-11T11:26:33.348+0000] {task_command.py:426} INFO - Running <TaskInstance: trigger_dag_id.file_sensor manual__2024-06-11T11:26:23.981118+00:00 [running]> on host 7c4889ca854e
[2024-06-11T11:26:33.466+0000] {taskinstance.py:2648} INFO - Exporting env vars: AIRFLOW_CTX_DAG_OWNER='***' AIRFLOW_CTX_DAG_ID='trigger_dag_id' AIRFLOW_CTX_TASK_ID='file_sensor' AIRFLOW_CTX_EXECUTION_DATE='2024-06-11T11:26:23.981118+00:00' AIRFLOW_CTX_TRY_NUMBER='1' AIRFLOW_CTX_DAG_RUN_ID='manual__2024-06-11T11:26:23.981118+00:00'
[2024-06-11T11:26:33.470+0000] {taskinstance.py:430} INFO - ::endgroup::
[2024-06-11T11:26:33.471+0000] {baseoperator.py:399} WARNING - FileSensor.execute cannot be called outside TaskInstance!
[2024-06-11T11:26:33.482+0000] {connectionpool.py:874} WARNING - Retrying (Retry(total=2, connect=None, read=None, redirect=None, status=None)) after connection broken by 'NameResolutionError("<urllib3.connection.HTTPConnection object at 0x7f3d40c7d610>: Failed to resolve 'vault' ([Errno -2] Name or service not known)")': /v1/auth/token/lookup-self
[2024-06-11T11:26:33.689+0000] {connectionpool.py:874} WARNING - Retrying (Retry(total=1, connect=None, read=None, redirect=None, status=None)) after connection broken by 'NameResolutionError("<urllib3.connection.HTTPConnection object at 0x7f3d1b89b4a0>: Failed to resolve 'vault' ([Errno -2] Name or service not known)")': /v1/auth/token/lookup-self
[2024-06-11T11:26:34.098+0000] {connectionpool.py:874} WARNING - Retrying (Retry(total=0, connect=None, read=None, redirect=None, status=None)) after connection broken by 'NameResolutionError("<urllib3.connection.HTTPConnection object at 0x7f3d1b89b680>: Failed to resolve 'vault' ([Errno -2] Name or service not known)")': /v1/auth/token/lookup-self
[2024-06-11T11:26:34.104+0000] {connection.py:513} ERROR - Unable to retrieve connection from secrets backend (VaultBackend). Checking subsequent secrets backend.
Traceback (most recent call last):
  File "/home/airflow/.local/lib/python3.12/site-packages/urllib3/connection.py", line 198, in _new_conn
    sock = connection.create_connection(
           ^^^^^^^^^^^^^^^^^^^^^^^^^^^^^
  File "/home/airflow/.local/lib/python3.12/site-packages/urllib3/util/connection.py", line 60, in create_connection
    for res in socket.getaddrinfo(host, port, family, socket.SOCK_STREAM):
               ^^^^^^^^^^^^^^^^^^^^^^^^^^^^^^^^^^^^^^^^^^^^^^^^^^^^^^^^^^
  File "/usr/local/lib/python3.12/socket.py", line 963, in getaddrinfo
    for res in _socket.getaddrinfo(host, port, family, type, proto, flags):
               ^^^^^^^^^^^^^^^^^^^^^^^^^^^^^^^^^^^^^^^^^^^^^^^^^^^^^^^^^^^
socket.gaierror: [Errno -2] Name or service not known

The above exception was the direct cause of the following exception:

Traceback (most recent call last):
  File "/home/airflow/.local/lib/python3.12/site-packages/urllib3/connectionpool.py", line 793, in urlopen
    response = self._make_request(
               ^^^^^^^^^^^^^^^^^^^
  File "/home/airflow/.local/lib/python3.12/site-packages/urllib3/connectionpool.py", line 496, in _make_request
    conn.request(
  File "/home/airflow/.local/lib/python3.12/site-packages/urllib3/connection.py", line 400, in request
    self.endheaders()
  File "/usr/local/lib/python3.12/http/client.py", line 1331, in endheaders
    self._send_output(message_body, encode_chunked=encode_chunked)
  File "/usr/local/lib/python3.12/http/client.py", line 1091, in _send_output
    self.send(msg)
  File "/usr/local/lib/python3.12/http/client.py", line 1035, in send
    self.connect()
  File "/home/airflow/.local/lib/python3.12/site-packages/urllib3/connection.py", line 238, in connect
    self.sock = self._new_conn()
                ^^^^^^^^^^^^^^^^
  File "/home/airflow/.local/lib/python3.12/site-packages/urllib3/connection.py", line 205, in _new_conn
    raise NameResolutionError(self.host, self, e) from e
urllib3.exceptions.NameResolutionError: <urllib3.connection.HTTPConnection object at 0x7f3d1b89b9b0>: Failed to resolve 'vault' ([Errno -2] Name or service not known)

The above exception was the direct cause of the following exception:

Traceback (most recent call last):
  File "/home/airflow/.local/lib/python3.12/site-packages/requests/adapters.py", line 486, in send
    resp = conn.urlopen(
           ^^^^^^^^^^^^^
  File "/home/airflow/.local/lib/python3.12/site-packages/urllib3/connectionpool.py", line 877, in urlopen
    return self.urlopen(
           ^^^^^^^^^^^^^
  File "/home/airflow/.local/lib/python3.12/site-packages/urllib3/connectionpool.py", line 877, in urlopen
    return self.urlopen(
           ^^^^^^^^^^^^^
  File "/home/airflow/.local/lib/python3.12/site-packages/urllib3/connectionpool.py", line 877, in urlopen
    return self.urlopen(
           ^^^^^^^^^^^^^
  File "/home/airflow/.local/lib/python3.12/site-packages/urllib3/connectionpool.py", line 847, in urlopen
    retries = retries.increment(
              ^^^^^^^^^^^^^^^^^^
  File "/home/airflow/.local/lib/python3.12/site-packages/urllib3/util/retry.py", line 515, in increment
    raise MaxRetryError(_pool, url, reason) from reason  # type: ignore[arg-type]
    ^^^^^^^^^^^^^^^^^^^^^^^^^^^^^^^^^^^^^^^^^^^^^^^^^^^
urllib3.exceptions.MaxRetryError: HTTPConnectionPool(host='vault', port=8200): Max retries exceeded with url: /v1/auth/token/lookup-self (Caused by NameResolutionError("<urllib3.connection.HTTPConnection object at 0x7f3d1b89b9b0>: Failed to resolve 'vault' ([Errno -2] Name or service not known)"))

During handling of the above exception, another exception occurred:

Traceback (most recent call last):
  File "/home/airflow/.local/lib/python3.12/site-packages/airflow/models/connection.py", line 508, in get_connection_from_secrets
    conn = secrets_backend.get_connection(conn_id=conn_id)
           ^^^^^^^^^^^^^^^^^^^^^^^^^^^^^^^^^^^^^^^^^^^^^^^
  File "/home/airflow/.local/lib/python3.12/site-packages/airflow/providers/hashicorp/secrets/vault.py", line 221, in get_connection
    response = self.get_response(conn_id)
               ^^^^^^^^^^^^^^^^^^^^^^^^^^
  File "/home/airflow/.local/lib/python3.12/site-packages/airflow/providers/hashicorp/secrets/vault.py", line 184, in get_response
    return self.vault_client.get_secret(
           ^^^^^^^^^^^^^^^^^^^^^^^^^^^^^
  File "/home/airflow/.local/lib/python3.12/site-packages/airflow/providers/hashicorp/_internal_client/vault_client.py", line 376, in get_secret
    response = self.client.secrets.kv.v2.read_secret_version(
               ^^^^^^^^^^^
  File "/home/airflow/.local/lib/python3.12/site-packages/airflow/providers/hashicorp/_internal_client/vault_client.py", line 182, in client
    if not self._client.is_authenticated():
           ^^^^^^^^^^^^
  File "/usr/local/lib/python3.12/functools.py", line 995, in __get__
    val = self.func(instance)
          ^^^^^^^^^^^^^^^^^^^
  File "/home/airflow/.local/lib/python3.12/site-packages/airflow/providers/hashicorp/_internal_client/vault_client.py", line 236, in _client
    if _client.is_authenticated():
       ^^^^^^^^^^^^^^^^^^^^^^^^^^
  File "/home/airflow/.local/lib/python3.12/site-packages/hvac/v1/__init__.py", line 512, in is_authenticated
    self.lookup_token()
  File "/home/airflow/.local/lib/python3.12/site-packages/hvac/v1/__init__.py", line 433, in lookup_token
    return self._adapter.get(path, wrap_ttl=wrap_ttl)
           ^^^^^^^^^^^^^^^^^^^^^^^^^^^^^^^^^^^^^^^^^^
  File "/home/airflow/.local/lib/python3.12/site-packages/hvac/adapters.py", line 146, in get
    return self.request("get", url, **kwargs)
           ^^^^^^^^^^^^^^^^^^^^^^^^^^^^^^^^^^
  File "/home/airflow/.local/lib/python3.12/site-packages/hvac/adapters.py", line 408, in request
    response = super().request(*args, **kwargs)
               ^^^^^^^^^^^^^^^^^^^^^^^^^^^^^^^^
  File "/home/airflow/.local/lib/python3.12/site-packages/hvac/adapters.py", line 367, in request
    response = self.session.request(
               ^^^^^^^^^^^^^^^^^^^^^
  File "/home/airflow/.local/lib/python3.12/site-packages/requests/sessions.py", line 589, in request
    resp = self.send(prep, **send_kwargs)
           ^^^^^^^^^^^^^^^^^^^^^^^^^^^^^^
  File "/home/airflow/.local/lib/python3.12/site-packages/requests/sessions.py", line 703, in send
    r = adapter.send(request, **kwargs)
        ^^^^^^^^^^^^^^^^^^^^^^^^^^^^^^^
  File "/home/airflow/.local/lib/python3.12/site-packages/requests/adapters.py", line 519, in send
    raise ConnectionError(e, request=request)
requests.exceptions.ConnectionError: HTTPConnectionPool(host='vault', port=8200): Max retries exceeded with url: /v1/auth/token/lookup-self (Caused by NameResolutionError("<urllib3.connection.HTTPConnection object at 0x7f3d1b89b9b0>: Failed to resolve 'vault' ([Errno -2] Name or service not known)"))
[2024-06-11T11:26:34.127+0000] {base.py:84} INFO - Using connection ID 'fs_default' for task execution.
[2024-06-11T11:26:34.130+0000] {filesystem.py:85} INFO - Poking for file /opt/***/TRIGGER_FILE/file.txt
[2024-06-11T11:27:34.133+0000] {filesystem.py:85} INFO - Poking for file /opt/***/TRIGGER_FILE/file.txt
[2024-06-11T11:28:34.138+0000] {filesystem.py:85} INFO - Poking for file /opt/***/TRIGGER_FILE/file.txt
[2024-06-11T11:29:19.775+0000] {local_task_job_runner.py:310} WARNING - State of this instance has been externally set to upstream_failed. Terminating instance.
[2024-06-11T11:29:19.777+0000] {local_task_job_runner.py:222} INFO - ::endgroup::
[2024-06-11T11:29:19.780+0000] {process_utils.py:132} INFO - Sending 15 to group 1179. PIDs of all processes in the group: [1179]
[2024-06-11T11:29:19.781+0000] {process_utils.py:87} INFO - Sending the signal 15 to group 1179
[2024-06-11T11:29:19.782+0000] {taskinstance.py:2611} ERROR - Received SIGTERM. Terminating subprocesses.
[2024-06-11T11:29:19.782+0000] {taskinstance.py:441} INFO - ::group::Post task execution logs
[2024-06-11T11:29:19.813+0000] {process_utils.py:80} INFO - Process psutil.Process(pid=1179, status='terminated', exitcode=0, started='11:26:32') (1179) terminated with exit code 0
