[2024-06-10T11:52:07.794+0000] {local_task_job_runner.py:120} INFO - ::group::Pre task execution logs
[2024-06-10T11:52:07.863+0000] {taskinstance.py:2076} INFO - Dependencies all met for dep_context=non-requeueable deps ti=<TaskInstance: trigger_dag_id.file_sensor manual__2024-06-10T11:51:54.025803+00:00 [queued]>
[2024-06-10T11:52:07.884+0000] {taskinstance.py:2076} INFO - Dependencies all met for dep_context=requeueable deps ti=<TaskInstance: trigger_dag_id.file_sensor manual__2024-06-10T11:51:54.025803+00:00 [queued]>
[2024-06-10T11:52:07.887+0000] {taskinstance.py:2306} INFO - Starting attempt 1 of 1
[2024-06-10T11:52:07.929+0000] {taskinstance.py:2330} INFO - Executing <Task(FileSensor): file_sensor> on 2024-06-10 11:51:54.025803+00:00
[2024-06-10T11:52:08.031+0000] {warnings.py:110} WARNING - /home/***/.local/lib/python3.12/site-packages/***/task/task_runner/standard_task_runner.py:61: DeprecationWarning: This process (pid=64) is multi-threaded, use of fork() may lead to deadlocks in the child.
  pid = os.fork()

[2024-06-10T11:52:08.080+0000] {standard_task_runner.py:63} INFO - Started process 66 to run task
[2024-06-10T11:52:08.046+0000] {standard_task_runner.py:90} INFO - Running: ['***', 'tasks', 'run', 'trigger_dag_id', 'file_sensor', 'manual__2024-06-10T11:51:54.025803+00:00', '--job-id', '706', '--raw', '--subdir', 'DAGS_FOLDER/trigger_dag.py.zip/trigger_dag.py', '--cfg-path', '/tmp/tmpcn71qv_7']
[2024-06-10T11:52:08.092+0000] {standard_task_runner.py:91} INFO - Job 706: Subtask file_sensor
[2024-06-10T11:52:08.242+0000] {task_command.py:426} INFO - Running <TaskInstance: trigger_dag_id.file_sensor manual__2024-06-10T11:51:54.025803+00:00 [running]> on host 485325dd593b
[2024-06-10T11:52:08.533+0000] {taskinstance.py:2648} INFO - Exporting env vars: AIRFLOW_CTX_DAG_OWNER='***' AIRFLOW_CTX_DAG_ID='trigger_dag_id' AIRFLOW_CTX_TASK_ID='file_sensor' AIRFLOW_CTX_EXECUTION_DATE='2024-06-10T11:51:54.025803+00:00' AIRFLOW_CTX_TRY_NUMBER='1' AIRFLOW_CTX_DAG_RUN_ID='manual__2024-06-10T11:51:54.025803+00:00'
[2024-06-10T11:52:08.537+0000] {taskinstance.py:430} INFO - ::endgroup::
[2024-06-10T11:52:08.538+0000] {baseoperator.py:399} WARNING - FileSensor.execute cannot be called outside TaskInstance!
[2024-06-10T11:52:08.556+0000] {connectionpool.py:874} WARNING - Retrying (Retry(total=2, connect=None, read=None, redirect=None, status=None)) after connection broken by 'NameResolutionError("<urllib3.connection.HTTPConnection object at 0x7f0b7da5b590>: Failed to resolve 'vault' ([Errno -2] Name or service not known)")': /v1/auth/token/lookup-self
[2024-06-10T11:52:08.765+0000] {connectionpool.py:874} WARNING - Retrying (Retry(total=1, connect=None, read=None, redirect=None, status=None)) after connection broken by 'NameResolutionError("<urllib3.connection.HTTPConnection object at 0x7f0b7dd76270>: Failed to resolve 'vault' ([Errno -2] Name or service not known)")': /v1/auth/token/lookup-self
[2024-06-10T11:52:09.180+0000] {connectionpool.py:874} WARNING - Retrying (Retry(total=0, connect=None, read=None, redirect=None, status=None)) after connection broken by 'NameResolutionError("<urllib3.connection.HTTPConnection object at 0x7f0b7dd76720>: Failed to resolve 'vault' ([Errno -2] Name or service not known)")': /v1/auth/token/lookup-self
[2024-06-10T11:52:09.196+0000] {connection.py:513} ERROR - Unable to retrieve connection from secrets backend (VaultBackend). Checking subsequent secrets backend.
Traceback (most recent call last):
  File "/home/airflow/.local/lib/python3.12/site-packages/urllib3/connection.py", line 198, in _new_conn
    sock = connection.create_connection(
           ^^^^^^^^^^^^^^^^^^^^^^^^^^^^^
  File "/home/airflow/.local/lib/python3.12/site-packages/urllib3/util/connection.py", line 60, in create_connection
    for res in socket.getaddrinfo(host, port, family, socket.SOCK_STREAM):
               ^^^^^^^^^^^^^^^^^^^^^^^^^^^^^^^^^^^^^^^^^^^^^^^^^^^^^^^^^^
  File "/usr/local/lib/python3.12/socket.py", line 963, in getaddrinfo
    for res in _socket.getaddrinfo(host, port, family, type, proto, flags):
               ^^^^^^^^^^^^^^^^^^^^^^^^^^^^^^^^^^^^^^^^^^^^^^^^^^^^^^^^^^^
socket.gaierror: [Errno -2] Name or service not known

The above exception was the direct cause of the following exception:

Traceback (most recent call last):
  File "/home/airflow/.local/lib/python3.12/site-packages/urllib3/connectionpool.py", line 793, in urlopen
    response = self._make_request(
               ^^^^^^^^^^^^^^^^^^^
  File "/home/airflow/.local/lib/python3.12/site-packages/urllib3/connectionpool.py", line 496, in _make_request
    conn.request(
  File "/home/airflow/.local/lib/python3.12/site-packages/urllib3/connection.py", line 400, in request
    self.endheaders()
  File "/usr/local/lib/python3.12/http/client.py", line 1331, in endheaders
    self._send_output(message_body, encode_chunked=encode_chunked)
  File "/usr/local/lib/python3.12/http/client.py", line 1091, in _send_output
    self.send(msg)
  File "/usr/local/lib/python3.12/http/client.py", line 1035, in send
    self.connect()
  File "/home/airflow/.local/lib/python3.12/site-packages/urllib3/connection.py", line 238, in connect
    self.sock = self._new_conn()
                ^^^^^^^^^^^^^^^^
  File "/home/airflow/.local/lib/python3.12/site-packages/urllib3/connection.py", line 205, in _new_conn
    raise NameResolutionError(self.host, self, e) from e
urllib3.exceptions.NameResolutionError: <urllib3.connection.HTTPConnection object at 0x7f0b7dd76ae0>: Failed to resolve 'vault' ([Errno -2] Name or service not known)

The above exception was the direct cause of the following exception:

Traceback (most recent call last):
  File "/home/airflow/.local/lib/python3.12/site-packages/requests/adapters.py", line 486, in send
    resp = conn.urlopen(
           ^^^^^^^^^^^^^
  File "/home/airflow/.local/lib/python3.12/site-packages/urllib3/connectionpool.py", line 877, in urlopen
    return self.urlopen(
           ^^^^^^^^^^^^^
  File "/home/airflow/.local/lib/python3.12/site-packages/urllib3/connectionpool.py", line 877, in urlopen
    return self.urlopen(
           ^^^^^^^^^^^^^
  File "/home/airflow/.local/lib/python3.12/site-packages/urllib3/connectionpool.py", line 877, in urlopen
    return self.urlopen(
           ^^^^^^^^^^^^^
  File "/home/airflow/.local/lib/python3.12/site-packages/urllib3/connectionpool.py", line 847, in urlopen
    retries = retries.increment(
              ^^^^^^^^^^^^^^^^^^
  File "/home/airflow/.local/lib/python3.12/site-packages/urllib3/util/retry.py", line 515, in increment
    raise MaxRetryError(_pool, url, reason) from reason  # type: ignore[arg-type]
    ^^^^^^^^^^^^^^^^^^^^^^^^^^^^^^^^^^^^^^^^^^^^^^^^^^^
urllib3.exceptions.MaxRetryError: HTTPConnectionPool(host='vault', port=8200): Max retries exceeded with url: /v1/auth/token/lookup-self (Caused by NameResolutionError("<urllib3.connection.HTTPConnection object at 0x7f0b7dd76ae0>: Failed to resolve 'vault' ([Errno -2] Name or service not known)"))

During handling of the above exception, another exception occurred:

Traceback (most recent call last):
  File "/home/airflow/.local/lib/python3.12/site-packages/airflow/models/connection.py", line 508, in get_connection_from_secrets
    conn = secrets_backend.get_connection(conn_id=conn_id)
           ^^^^^^^^^^^^^^^^^^^^^^^^^^^^^^^^^^^^^^^^^^^^^^^
  File "/home/airflow/.local/lib/python3.12/site-packages/airflow/providers/hashicorp/secrets/vault.py", line 221, in get_connection
    response = self.get_response(conn_id)
               ^^^^^^^^^^^^^^^^^^^^^^^^^^
  File "/home/airflow/.local/lib/python3.12/site-packages/airflow/providers/hashicorp/secrets/vault.py", line 184, in get_response
    return self.vault_client.get_secret(
           ^^^^^^^^^^^^^^^^^^^^^^^^^^^^^
  File "/home/airflow/.local/lib/python3.12/site-packages/airflow/providers/hashicorp/_internal_client/vault_client.py", line 376, in get_secret
    response = self.client.secrets.kv.v2.read_secret_version(
               ^^^^^^^^^^^
  File "/home/airflow/.local/lib/python3.12/site-packages/airflow/providers/hashicorp/_internal_client/vault_client.py", line 182, in client
    if not self._client.is_authenticated():
           ^^^^^^^^^^^^
  File "/usr/local/lib/python3.12/functools.py", line 995, in __get__
    val = self.func(instance)
          ^^^^^^^^^^^^^^^^^^^
  File "/home/airflow/.local/lib/python3.12/site-packages/airflow/providers/hashicorp/_internal_client/vault_client.py", line 236, in _client
    if _client.is_authenticated():
       ^^^^^^^^^^^^^^^^^^^^^^^^^^
  File "/home/airflow/.local/lib/python3.12/site-packages/hvac/v1/__init__.py", line 512, in is_authenticated
    self.lookup_token()
  File "/home/airflow/.local/lib/python3.12/site-packages/hvac/v1/__init__.py", line 433, in lookup_token
    return self._adapter.get(path, wrap_ttl=wrap_ttl)
           ^^^^^^^^^^^^^^^^^^^^^^^^^^^^^^^^^^^^^^^^^^
  File "/home/airflow/.local/lib/python3.12/site-packages/hvac/adapters.py", line 146, in get
    return self.request("get", url, **kwargs)
           ^^^^^^^^^^^^^^^^^^^^^^^^^^^^^^^^^^
  File "/home/airflow/.local/lib/python3.12/site-packages/hvac/adapters.py", line 408, in request
    response = super().request(*args, **kwargs)
               ^^^^^^^^^^^^^^^^^^^^^^^^^^^^^^^^
  File "/home/airflow/.local/lib/python3.12/site-packages/hvac/adapters.py", line 367, in request
    response = self.session.request(
               ^^^^^^^^^^^^^^^^^^^^^
  File "/home/airflow/.local/lib/python3.12/site-packages/requests/sessions.py", line 589, in request
    resp = self.send(prep, **send_kwargs)
           ^^^^^^^^^^^^^^^^^^^^^^^^^^^^^^
  File "/home/airflow/.local/lib/python3.12/site-packages/requests/sessions.py", line 703, in send
    r = adapter.send(request, **kwargs)
        ^^^^^^^^^^^^^^^^^^^^^^^^^^^^^^^
  File "/home/airflow/.local/lib/python3.12/site-packages/requests/adapters.py", line 519, in send
    raise ConnectionError(e, request=request)
requests.exceptions.ConnectionError: HTTPConnectionPool(host='vault', port=8200): Max retries exceeded with url: /v1/auth/token/lookup-self (Caused by NameResolutionError("<urllib3.connection.HTTPConnection object at 0x7f0b7dd76ae0>: Failed to resolve 'vault' ([Errno -2] Name or service not known)"))
[2024-06-10T11:52:09.232+0000] {base.py:84} INFO - Using connection ID 'fs_default' for task execution.
[2024-06-10T11:52:09.233+0000] {filesystem.py:85} INFO - Poking for file /opt/***/TRIGGER_FILE/file.txt
[2024-06-10T11:53:09.242+0000] {filesystem.py:85} INFO - Poking for file /opt/***/TRIGGER_FILE/file.txt
[2024-06-10T11:53:09.256+0000] {filesystem.py:89} INFO - Found File /opt/***/TRIGGER_FILE/file.txt last modified: 20240411090055
[2024-06-10T11:53:09.257+0000] {base.py:294} INFO - Success criteria met. Exiting.
[2024-06-10T11:53:09.257+0000] {filesystem.py:85} INFO - Poking for file /opt/***/TRIGGER_FILE/file.txt
[2024-06-10T11:53:09.258+0000] {filesystem.py:89} INFO - Found File /opt/***/TRIGGER_FILE/file.txt last modified: 20240411090055
[2024-06-10T11:53:09.260+0000] {taskinstance.py:441} INFO - ::group::Post task execution logs
[2024-06-10T11:53:09.295+0000] {taskinstance.py:1206} INFO - Marking task as SUCCESS. dag_id=trigger_dag_id, task_id=file_sensor, run_id=manual__2024-06-10T11:51:54.025803+00:00, execution_date=20240610T115154, start_date=20240610T115207, end_date=20240610T115309
[2024-06-10T11:53:09.344+0000] {local_task_job_runner.py:240} INFO - Task exited with return code 0
[2024-06-10T11:53:09.429+0000] {taskinstance.py:3498} INFO - 1 downstream tasks scheduled from follow-on schedule check
[2024-06-10T11:53:09.431+0000] {local_task_job_runner.py:222} INFO - ::endgroup::
