[2024-06-10T14:38:23.647+0000] {local_task_job_runner.py:120} INFO - ::group::Pre task execution logs
[2024-06-10T14:38:23.698+0000] {taskinstance.py:2076} INFO - Dependencies all met for dep_context=non-requeueable deps ti=<TaskInstance: trigger_dag_id.file_sensor manual__2024-06-10T14:38:02.139605+00:00 [queued]>
[2024-06-10T14:38:23.714+0000] {taskinstance.py:2076} INFO - Dependencies all met for dep_context=requeueable deps ti=<TaskInstance: trigger_dag_id.file_sensor manual__2024-06-10T14:38:02.139605+00:00 [queued]>
[2024-06-10T14:38:23.715+0000] {taskinstance.py:2306} INFO - Starting attempt 1 of 1
[2024-06-10T14:38:23.739+0000] {taskinstance.py:2330} INFO - Executing <Task(FileSensor): file_sensor> on 2024-06-10 14:38:02.139605+00:00
[2024-06-10T14:38:23.753+0000] {warnings.py:110} WARNING - /home/***/.local/lib/python3.12/site-packages/***/task/task_runner/standard_task_runner.py:61: DeprecationWarning: This process (pid=792) is multi-threaded, use of fork() may lead to deadlocks in the child.
  pid = os.fork()

[2024-06-10T14:38:23.757+0000] {standard_task_runner.py:63} INFO - Started process 801 to run task
[2024-06-10T14:38:23.757+0000] {standard_task_runner.py:90} INFO - Running: ['***', 'tasks', 'run', 'trigger_dag_id', 'file_sensor', 'manual__2024-06-10T14:38:02.139605+00:00', '--job-id', '757', '--raw', '--subdir', 'DAGS_FOLDER/trigger_dag.py', '--cfg-path', '/tmp/tmp3tg_3k8m']
[2024-06-10T14:38:23.762+0000] {standard_task_runner.py:91} INFO - Job 757: Subtask file_sensor
[2024-06-10T14:38:23.958+0000] {task_command.py:426} INFO - Running <TaskInstance: trigger_dag_id.file_sensor manual__2024-06-10T14:38:02.139605+00:00 [running]> on host 485325dd593b
[2024-06-10T14:38:24.201+0000] {taskinstance.py:2648} INFO - Exporting env vars: AIRFLOW_CTX_DAG_OWNER='***' AIRFLOW_CTX_DAG_ID='trigger_dag_id' AIRFLOW_CTX_TASK_ID='file_sensor' AIRFLOW_CTX_EXECUTION_DATE='2024-06-10T14:38:02.139605+00:00' AIRFLOW_CTX_TRY_NUMBER='1' AIRFLOW_CTX_DAG_RUN_ID='manual__2024-06-10T14:38:02.139605+00:00'
[2024-06-10T14:38:24.205+0000] {taskinstance.py:430} INFO - ::endgroup::
[2024-06-10T14:38:24.206+0000] {baseoperator.py:399} WARNING - FileSensor.execute cannot be called outside TaskInstance!
[2024-06-10T14:38:24.233+0000] {connectionpool.py:874} WARNING - Retrying (Retry(total=2, connect=None, read=None, redirect=None, status=None)) after connection broken by 'NameResolutionError("<urllib3.connection.HTTPConnection object at 0x7f0b7d106510>: Failed to resolve 'vault' ([Errno -2] Name or service not known)")': /v1/auth/token/lookup-self
[2024-06-10T14:38:24.445+0000] {connectionpool.py:874} WARNING - Retrying (Retry(total=1, connect=None, read=None, redirect=None, status=None)) after connection broken by 'NameResolutionError("<urllib3.connection.HTTPConnection object at 0x7f0b7d14cbc0>: Failed to resolve 'vault' ([Errno -2] Name or service not known)")': /v1/auth/token/lookup-self
[2024-06-10T14:38:24.856+0000] {connectionpool.py:874} WARNING - Retrying (Retry(total=0, connect=None, read=None, redirect=None, status=None)) after connection broken by 'NameResolutionError("<urllib3.connection.HTTPConnection object at 0x7f0b7d14d010>: Failed to resolve 'vault' ([Errno -2] Name or service not known)")': /v1/auth/token/lookup-self
[2024-06-10T14:38:24.864+0000] {connection.py:513} ERROR - Unable to retrieve connection from secrets backend (VaultBackend). Checking subsequent secrets backend.
Traceback (most recent call last):
  File "/home/airflow/.local/lib/python3.12/site-packages/urllib3/connection.py", line 198, in _new_conn
    sock = connection.create_connection(
           ^^^^^^^^^^^^^^^^^^^^^^^^^^^^^
  File "/home/airflow/.local/lib/python3.12/site-packages/urllib3/util/connection.py", line 60, in create_connection
    for res in socket.getaddrinfo(host, port, family, socket.SOCK_STREAM):
               ^^^^^^^^^^^^^^^^^^^^^^^^^^^^^^^^^^^^^^^^^^^^^^^^^^^^^^^^^^
  File "/usr/local/lib/python3.12/socket.py", line 963, in getaddrinfo
    for res in _socket.getaddrinfo(host, port, family, type, proto, flags):
               ^^^^^^^^^^^^^^^^^^^^^^^^^^^^^^^^^^^^^^^^^^^^^^^^^^^^^^^^^^^
socket.gaierror: [Errno -2] Name or service not known

The above exception was the direct cause of the following exception:

Traceback (most recent call last):
  File "/home/airflow/.local/lib/python3.12/site-packages/urllib3/connectionpool.py", line 793, in urlopen
    response = self._make_request(
               ^^^^^^^^^^^^^^^^^^^
  File "/home/airflow/.local/lib/python3.12/site-packages/urllib3/connectionpool.py", line 496, in _make_request
    conn.request(
  File "/home/airflow/.local/lib/python3.12/site-packages/urllib3/connection.py", line 400, in request
    self.endheaders()
  File "/usr/local/lib/python3.12/http/client.py", line 1331, in endheaders
    self._send_output(message_body, encode_chunked=encode_chunked)
  File "/usr/local/lib/python3.12/http/client.py", line 1091, in _send_output
    self.send(msg)
  File "/usr/local/lib/python3.12/http/client.py", line 1035, in send
    self.connect()
  File "/home/airflow/.local/lib/python3.12/site-packages/urllib3/connection.py", line 238, in connect
    self.sock = self._new_conn()
                ^^^^^^^^^^^^^^^^
  File "/home/airflow/.local/lib/python3.12/site-packages/urllib3/connection.py", line 205, in _new_conn
    raise NameResolutionError(self.host, self, e) from e
urllib3.exceptions.NameResolutionError: <urllib3.connection.HTTPConnection object at 0x7f0b7d14d4f0>: Failed to resolve 'vault' ([Errno -2] Name or service not known)

The above exception was the direct cause of the following exception:

Traceback (most recent call last):
  File "/home/airflow/.local/lib/python3.12/site-packages/requests/adapters.py", line 486, in send
    resp = conn.urlopen(
           ^^^^^^^^^^^^^
  File "/home/airflow/.local/lib/python3.12/site-packages/urllib3/connectionpool.py", line 877, in urlopen
    return self.urlopen(
           ^^^^^^^^^^^^^
  File "/home/airflow/.local/lib/python3.12/site-packages/urllib3/connectionpool.py", line 877, in urlopen
    return self.urlopen(
           ^^^^^^^^^^^^^
  File "/home/airflow/.local/lib/python3.12/site-packages/urllib3/connectionpool.py", line 877, in urlopen
    return self.urlopen(
           ^^^^^^^^^^^^^
  File "/home/airflow/.local/lib/python3.12/site-packages/urllib3/connectionpool.py", line 847, in urlopen
    retries = retries.increment(
              ^^^^^^^^^^^^^^^^^^
  File "/home/airflow/.local/lib/python3.12/site-packages/urllib3/util/retry.py", line 515, in increment
    raise MaxRetryError(_pool, url, reason) from reason  # type: ignore[arg-type]
    ^^^^^^^^^^^^^^^^^^^^^^^^^^^^^^^^^^^^^^^^^^^^^^^^^^^
urllib3.exceptions.MaxRetryError: HTTPConnectionPool(host='vault', port=8200): Max retries exceeded with url: /v1/auth/token/lookup-self (Caused by NameResolutionError("<urllib3.connection.HTTPConnection object at 0x7f0b7d14d4f0>: Failed to resolve 'vault' ([Errno -2] Name or service not known)"))

During handling of the above exception, another exception occurred:

Traceback (most recent call last):
  File "/home/airflow/.local/lib/python3.12/site-packages/airflow/models/connection.py", line 508, in get_connection_from_secrets
    conn = secrets_backend.get_connection(conn_id=conn_id)
           ^^^^^^^^^^^^^^^^^^^^^^^^^^^^^^^^^^^^^^^^^^^^^^^
  File "/home/airflow/.local/lib/python3.12/site-packages/airflow/providers/hashicorp/secrets/vault.py", line 221, in get_connection
    response = self.get_response(conn_id)
               ^^^^^^^^^^^^^^^^^^^^^^^^^^
  File "/home/airflow/.local/lib/python3.12/site-packages/airflow/providers/hashicorp/secrets/vault.py", line 184, in get_response
    return self.vault_client.get_secret(
           ^^^^^^^^^^^^^^^^^^^^^^^^^^^^^
  File "/home/airflow/.local/lib/python3.12/site-packages/airflow/providers/hashicorp/_internal_client/vault_client.py", line 376, in get_secret
    response = self.client.secrets.kv.v2.read_secret_version(
               ^^^^^^^^^^^
  File "/home/airflow/.local/lib/python3.12/site-packages/airflow/providers/hashicorp/_internal_client/vault_client.py", line 182, in client
    if not self._client.is_authenticated():
           ^^^^^^^^^^^^
  File "/usr/local/lib/python3.12/functools.py", line 995, in __get__
    val = self.func(instance)
          ^^^^^^^^^^^^^^^^^^^
  File "/home/airflow/.local/lib/python3.12/site-packages/airflow/providers/hashicorp/_internal_client/vault_client.py", line 236, in _client
    if _client.is_authenticated():
       ^^^^^^^^^^^^^^^^^^^^^^^^^^
  File "/home/airflow/.local/lib/python3.12/site-packages/hvac/v1/__init__.py", line 512, in is_authenticated
    self.lookup_token()
  File "/home/airflow/.local/lib/python3.12/site-packages/hvac/v1/__init__.py", line 433, in lookup_token
    return self._adapter.get(path, wrap_ttl=wrap_ttl)
           ^^^^^^^^^^^^^^^^^^^^^^^^^^^^^^^^^^^^^^^^^^
  File "/home/airflow/.local/lib/python3.12/site-packages/hvac/adapters.py", line 146, in get
    return self.request("get", url, **kwargs)
           ^^^^^^^^^^^^^^^^^^^^^^^^^^^^^^^^^^
  File "/home/airflow/.local/lib/python3.12/site-packages/hvac/adapters.py", line 408, in request
    response = super().request(*args, **kwargs)
               ^^^^^^^^^^^^^^^^^^^^^^^^^^^^^^^^
  File "/home/airflow/.local/lib/python3.12/site-packages/hvac/adapters.py", line 367, in request
    response = self.session.request(
               ^^^^^^^^^^^^^^^^^^^^^
  File "/home/airflow/.local/lib/python3.12/site-packages/requests/sessions.py", line 589, in request
    resp = self.send(prep, **send_kwargs)
           ^^^^^^^^^^^^^^^^^^^^^^^^^^^^^^
  File "/home/airflow/.local/lib/python3.12/site-packages/requests/sessions.py", line 703, in send
    r = adapter.send(request, **kwargs)
        ^^^^^^^^^^^^^^^^^^^^^^^^^^^^^^^
  File "/home/airflow/.local/lib/python3.12/site-packages/requests/adapters.py", line 519, in send
    raise ConnectionError(e, request=request)
requests.exceptions.ConnectionError: HTTPConnectionPool(host='vault', port=8200): Max retries exceeded with url: /v1/auth/token/lookup-self (Caused by NameResolutionError("<urllib3.connection.HTTPConnection object at 0x7f0b7d14d4f0>: Failed to resolve 'vault' ([Errno -2] Name or service not known)"))
[2024-06-10T14:38:24.904+0000] {base.py:84} INFO - Using connection ID 'fs_default' for task execution.
[2024-06-10T14:38:24.909+0000] {filesystem.py:85} INFO - Poking for file /opt/***/TRIGGER_FILE/file.txt
[2024-06-10T14:39:24.919+0000] {filesystem.py:85} INFO - Poking for file /opt/***/TRIGGER_FILE/file.txt
[2024-06-10T14:40:24.923+0000] {filesystem.py:85} INFO - Poking for file /opt/***/TRIGGER_FILE/file.txt
[2024-06-10T14:41:24.926+0000] {filesystem.py:85} INFO - Poking for file /opt/***/TRIGGER_FILE/file.txt
[2024-06-10T14:42:24.930+0000] {filesystem.py:85} INFO - Poking for file /opt/***/TRIGGER_FILE/file.txt
[2024-06-10T14:43:24.936+0000] {filesystem.py:85} INFO - Poking for file /opt/***/TRIGGER_FILE/file.txt
[2024-06-10T14:44:24.941+0000] {filesystem.py:85} INFO - Poking for file /opt/***/TRIGGER_FILE/file.txt
[2024-06-10T14:45:24.948+0000] {filesystem.py:85} INFO - Poking for file /opt/***/TRIGGER_FILE/file.txt
[2024-06-10T14:46:24.951+0000] {filesystem.py:85} INFO - Poking for file /opt/***/TRIGGER_FILE/file.txt
[2024-06-10T14:47:24.957+0000] {filesystem.py:85} INFO - Poking for file /opt/***/TRIGGER_FILE/file.txt
[2024-06-10T14:48:24.962+0000] {filesystem.py:85} INFO - Poking for file /opt/***/TRIGGER_FILE/file.txt
[2024-06-10T14:49:24.963+0000] {filesystem.py:85} INFO - Poking for file /opt/***/TRIGGER_FILE/file.txt
[2024-06-10T14:50:24.967+0000] {filesystem.py:85} INFO - Poking for file /opt/***/TRIGGER_FILE/file.txt
[2024-06-10T14:52:55.981+0000] {filesystem.py:85} INFO - Poking for file /opt/***/TRIGGER_FILE/file.txt
[2024-06-10T14:53:56.433+0000] {filesystem.py:85} INFO - Poking for file /opt/***/TRIGGER_FILE/file.txt
[2024-06-10T14:54:56.436+0000] {filesystem.py:85} INFO - Poking for file /opt/***/TRIGGER_FILE/file.txt
[2024-06-10T14:55:56.442+0000] {filesystem.py:85} INFO - Poking for file /opt/***/TRIGGER_FILE/file.txt
[2024-06-10T14:56:56.446+0000] {filesystem.py:85} INFO - Poking for file /opt/***/TRIGGER_FILE/file.txt
[2024-06-10T14:57:56.452+0000] {filesystem.py:85} INFO - Poking for file /opt/***/TRIGGER_FILE/file.txt
[2024-06-10T14:58:56.461+0000] {filesystem.py:85} INFO - Poking for file /opt/***/TRIGGER_FILE/file.txt
[2024-06-10T14:59:56.467+0000] {filesystem.py:85} INFO - Poking for file /opt/***/TRIGGER_FILE/file.txt
[2024-06-10T15:00:56.462+0000] {filesystem.py:85} INFO - Poking for file /opt/***/TRIGGER_FILE/file.txt
[2024-06-10T15:01:56.476+0000] {filesystem.py:85} INFO - Poking for file /opt/***/TRIGGER_FILE/file.txt
