[2024-06-11T15:35:08.783+0000] {local_task_job_runner.py:120} INFO - ::group::Pre task execution logs
[2024-06-11T15:35:08.867+0000] {taskinstance.py:2076} INFO - Dependencies all met for dep_context=non-requeueable deps ti=<TaskInstance: trigger_dag_id.file_sensor manual__2024-06-11T15:34:55.701630+00:00 [queued]>
[2024-06-11T15:35:08.958+0000] {taskinstance.py:2076} INFO - Dependencies all met for dep_context=requeueable deps ti=<TaskInstance: trigger_dag_id.file_sensor manual__2024-06-11T15:34:55.701630+00:00 [queued]>
[2024-06-11T15:35:08.959+0000] {taskinstance.py:2306} INFO - Starting attempt 1 of 1
[2024-06-11T15:35:09.003+0000] {taskinstance.py:2330} INFO - Executing <Task(CustomFileSensor): file_sensor> on 2024-06-11 15:34:55.701630+00:00
[2024-06-11T15:35:09.011+0000] {warnings.py:110} WARNING - /home/***/.local/lib/python3.12/site-packages/***/task/task_runner/standard_task_runner.py:61: DeprecationWarning: This process (pid=316) is multi-threaded, use of fork() may lead to deadlocks in the child.
  pid = os.fork()

[2024-06-11T15:35:09.013+0000] {standard_task_runner.py:63} INFO - Started process 318 to run task
[2024-06-11T15:35:09.014+0000] {standard_task_runner.py:90} INFO - Running: ['***', 'tasks', 'run', 'trigger_dag_id', 'file_sensor', 'manual__2024-06-11T15:34:55.701630+00:00', '--job-id', '842', '--raw', '--subdir', 'DAGS_FOLDER/trigger_dag.py', '--cfg-path', '/tmp/tmpxvmvzhrg']
[2024-06-11T15:35:09.018+0000] {standard_task_runner.py:91} INFO - Job 842: Subtask file_sensor
[2024-06-11T15:35:09.164+0000] {task_command.py:426} INFO - Running <TaskInstance: trigger_dag_id.file_sensor manual__2024-06-11T15:34:55.701630+00:00 [running]> on host e20108ce6780
[2024-06-11T15:35:09.565+0000] {taskinstance.py:2648} INFO - Exporting env vars: AIRFLOW_CTX_DAG_OWNER='***' AIRFLOW_CTX_DAG_ID='trigger_dag_id' AIRFLOW_CTX_TASK_ID='file_sensor' AIRFLOW_CTX_EXECUTION_DATE='2024-06-11T15:34:55.701630+00:00' AIRFLOW_CTX_TRY_NUMBER='1' AIRFLOW_CTX_DAG_RUN_ID='manual__2024-06-11T15:34:55.701630+00:00'
[2024-06-11T15:35:09.587+0000] {taskinstance.py:430} INFO - ::endgroup::
[2024-06-11T15:35:09.588+0000] {baseoperator.py:399} WARNING - CustomFileSensor.execute cannot be called outside TaskInstance!
[2024-06-11T15:35:09.589+0000] {connection.py:513} ERROR - Unable to retrieve connection from secrets backend (EnvironmentVariablesBackend). Checking subsequent secrets backend.
Traceback (most recent call last):
  File "/home/airflow/.local/lib/python3.12/site-packages/airflow/models/connection.py", line 508, in get_connection_from_secrets
    conn = secrets_backend.get_connection(conn_id=conn_id)
           ^^^^^^^^^^^^^^^^^^^^^^^^^^^^^^^^^^^^^^^^^^^^^^^
  File "/home/airflow/.local/lib/python3.12/site-packages/airflow/secrets/base_secrets.py", line 96, in get_connection
    value = self.get_conn_value(conn_id=conn_id)
            ^^^^^^^^^^^^^^^^^^^^^^^^^^^^^^^^^^^^
  File "/home/airflow/.local/lib/python3.12/site-packages/airflow/secrets/environment_variables.py", line 52, in get_conn_value
    return os.environ.get(CONN_ENV_PREFIX + conn_id.upper())
                                            ^^^^^^^^^^^^^
AttributeError: 'NoneType' object has no attribute 'upper'
[2024-06-11T15:35:09.629+0000] {taskinstance.py:441} INFO - ::group::Post task execution logs
[2024-06-11T15:35:09.674+0000] {taskinstance.py:2905} ERROR - Task failed with exception
Traceback (most recent call last):
  File "/home/airflow/.local/lib/python3.12/site-packages/airflow/models/taskinstance.py", line 465, in _execute_task
    result = _execute_callable(context=context, **execute_callable_kwargs)
             ^^^^^^^^^^^^^^^^^^^^^^^^^^^^^^^^^^^^^^^^^^^^^^^^^^^^^^^^^^^^^
  File "/home/airflow/.local/lib/python3.12/site-packages/airflow/models/taskinstance.py", line 432, in _execute_callable
    return execute_callable(context=context, **execute_callable_kwargs)
           ^^^^^^^^^^^^^^^^^^^^^^^^^^^^^^^^^^^^^^^^^^^^^^^^^^^^^^^^^^^^
  File "/home/airflow/.local/lib/python3.12/site-packages/airflow/models/baseoperator.py", line 400, in wrapper
    return func(self, *args, **kwargs)
           ^^^^^^^^^^^^^^^^^^^^^^^^^^^
  File "/home/airflow/.local/lib/python3.12/site-packages/airflow/sensors/filesystem.py", line 99, in execute
    super().execute(context=context)
  File "/home/airflow/.local/lib/python3.12/site-packages/airflow/models/baseoperator.py", line 400, in wrapper
    return func(self, *args, **kwargs)
           ^^^^^^^^^^^^^^^^^^^^^^^^^^^
  File "/home/airflow/.local/lib/python3.12/site-packages/airflow/sensors/base.py", line 264, in execute
    raise e
  File "/home/airflow/.local/lib/python3.12/site-packages/airflow/sensors/base.py", line 246, in execute
    poke_return = self.poke(context)
                  ^^^^^^^^^^^^^^^^^^
  File "/home/airflow/.local/lib/python3.12/site-packages/airflow/sensors/filesystem.py", line 85, in poke
    self.log.info("Poking for file %s", self.path)
                                        ^^^^^^^^^
  File "/usr/local/lib/python3.12/functools.py", line 995, in __get__
    val = self.func(instance)
          ^^^^^^^^^^^^^^^^^^^
  File "/home/airflow/.local/lib/python3.12/site-packages/airflow/sensors/filesystem.py", line 79, in path
    hook = FSHook(self.fs_conn_id)
           ^^^^^^^^^^^^^^^^^^^^^^^
  File "/home/airflow/.local/lib/python3.12/site-packages/airflow/hooks/filesystem.py", line 64, in __init__
    conn = self.get_connection(fs_conn_id)
           ^^^^^^^^^^^^^^^^^^^^^^^^^^^^^^^
  File "/home/airflow/.local/lib/python3.12/site-packages/airflow/hooks/base.py", line 83, in get_connection
    conn = Connection.get_connection_from_secrets(conn_id)
           ^^^^^^^^^^^^^^^^^^^^^^^^^^^^^^^^^^^^^^^^^^^^^^^
  File "/home/airflow/.local/lib/python3.12/site-packages/airflow/models/connection.py", line 519, in get_connection_from_secrets
    raise AirflowNotFoundException(f"The conn_id `{conn_id}` isn't defined")
airflow.exceptions.AirflowNotFoundException: The conn_id `None` isn't defined
[2024-06-11T15:35:09.704+0000] {taskinstance.py:1206} INFO - Marking task as FAILED. dag_id=trigger_dag_id, task_id=file_sensor, run_id=manual__2024-06-11T15:34:55.701630+00:00, execution_date=20240611T153455, start_date=20240611T153508, end_date=20240611T153509
[2024-06-11T15:35:09.752+0000] {standard_task_runner.py:110} ERROR - Failed to execute job 842 for task file_sensor (The conn_id `None` isn't defined; 318)
[2024-06-11T15:35:09.788+0000] {local_task_job_runner.py:240} INFO - Task exited with return code 1
[2024-06-11T15:35:09.870+0000] {taskinstance.py:3498} INFO - 0 downstream tasks scheduled from follow-on schedule check
[2024-06-11T15:35:09.879+0000] {local_task_job_runner.py:222} INFO - ::endgroup::
