[2024-06-07T10:04:13.183+0000] {local_task_job_runner.py:120} INFO - ::group::Pre task execution logs
[2024-06-07T10:04:13.222+0000] {taskinstance.py:2076} INFO - Dependencies all met for dep_context=non-requeueable deps ti=<TaskInstance: xdag_id_1.insert_new_row manual__2024-06-07T10:04:02.868356+00:00 [queued]>
[2024-06-07T10:04:13.237+0000] {taskinstance.py:2076} INFO - Dependencies all met for dep_context=requeueable deps ti=<TaskInstance: xdag_id_1.insert_new_row manual__2024-06-07T10:04:02.868356+00:00 [queued]>
[2024-06-07T10:04:13.238+0000] {taskinstance.py:2306} INFO - Starting attempt 1 of 1
[2024-06-07T10:04:13.262+0000] {taskinstance.py:2330} INFO - Executing <Task(SQLExecuteQueryOperator): insert_new_row> on 2024-06-07 10:04:02.868356+00:00
[2024-06-07T10:04:13.269+0000] {warnings.py:110} WARNING - /home/***/.local/lib/python3.12/site-packages/***/task/task_runner/standard_task_runner.py:61: DeprecationWarning: This process (pid=13110) is multi-threaded, use of fork() may lead to deadlocks in the child.
  pid = os.fork()

[2024-06-07T10:04:13.271+0000] {standard_task_runner.py:63} INFO - Started process 13112 to run task
[2024-06-07T10:04:13.272+0000] {standard_task_runner.py:90} INFO - Running: ['***', 'tasks', 'run', 'xdag_id_1', 'insert_new_row', 'manual__2024-06-07T10:04:02.868356+00:00', '--job-id', '573', '--raw', '--subdir', 'DAGS_FOLDER/jobs_dag.py', '--cfg-path', '/tmp/tmp0og54st0']
[2024-06-07T10:04:13.276+0000] {standard_task_runner.py:91} INFO - Job 573: Subtask insert_new_row
[2024-06-07T10:04:13.334+0000] {task_command.py:426} INFO - Running <TaskInstance: xdag_id_1.insert_new_row manual__2024-06-07T10:04:02.868356+00:00 [running]> on host db8c7b709f57
[2024-06-07T10:04:13.448+0000] {taskinstance.py:2648} INFO - Exporting env vars: AIRFLOW_CTX_DAG_OWNER='***' AIRFLOW_CTX_DAG_ID='xdag_id_1' AIRFLOW_CTX_TASK_ID='insert_new_row' AIRFLOW_CTX_EXECUTION_DATE='2024-06-07T10:04:02.868356+00:00' AIRFLOW_CTX_TRY_NUMBER='1' AIRFLOW_CTX_DAG_RUN_ID='manual__2024-06-07T10:04:02.868356+00:00'
[2024-06-07T10:04:13.451+0000] {taskinstance.py:430} INFO - ::endgroup::
[2024-06-07T10:04:13.452+0000] {sql.py:276} INFO - Executing: INSERT INTO table_name VALUES(%s, %s, %s);
[2024-06-07T10:04:13.461+0000] {base.py:84} INFO - Using connection ID 'postgres_default' for task execution.
[2024-06-07T10:04:13.470+0000] {base.py:84} INFO - Using connection ID 'postgres_default' for task execution.
[2024-06-07T10:04:13.475+0000] {sql.py:470} INFO - Running statement: INSERT INTO table_name VALUES(%s, %s, %s);, parameters: (11, 'default', datetime.datetime(2024, 6, 7, 10, 4, 11, 948706))
[2024-06-07T10:04:13.477+0000] {taskinstance.py:441} INFO - ::group::Post task execution logs
[2024-06-07T10:04:13.479+0000] {taskinstance.py:2905} ERROR - Task failed with exception
Traceback (most recent call last):
  File "/home/airflow/.local/lib/python3.12/site-packages/airflow/models/taskinstance.py", line 465, in _execute_task
    result = _execute_callable(context=context, **execute_callable_kwargs)
             ^^^^^^^^^^^^^^^^^^^^^^^^^^^^^^^^^^^^^^^^^^^^^^^^^^^^^^^^^^^^^
  File "/home/airflow/.local/lib/python3.12/site-packages/airflow/models/taskinstance.py", line 432, in _execute_callable
    return execute_callable(context=context, **execute_callable_kwargs)
           ^^^^^^^^^^^^^^^^^^^^^^^^^^^^^^^^^^^^^^^^^^^^^^^^^^^^^^^^^^^^
  File "/home/airflow/.local/lib/python3.12/site-packages/airflow/models/baseoperator.py", line 400, in wrapper
    return func(self, *args, **kwargs)
           ^^^^^^^^^^^^^^^^^^^^^^^^^^^
  File "/home/airflow/.local/lib/python3.12/site-packages/airflow/providers/common/sql/operators/sql.py", line 282, in execute
    output = hook.run(
             ^^^^^^^^^
  File "/home/airflow/.local/lib/python3.12/site-packages/airflow/providers/common/sql/hooks/sql.py", line 418, in run
    self._run_command(cur, sql_statement, parameters)
  File "/home/airflow/.local/lib/python3.12/site-packages/airflow/providers/common/sql/hooks/sql.py", line 473, in _run_command
    cur.execute(sql_statement, parameters)
psycopg2.errors.UndefinedTable: relation "table_name" does not exist
LINE 1: INSERT INTO table_name VALUES(11, 'default', '2024-06-07T10:...
                    ^

[2024-06-07T10:04:13.490+0000] {taskinstance.py:1206} INFO - Marking task as FAILED. dag_id=xdag_id_1, task_id=insert_new_row, run_id=manual__2024-06-07T10:04:02.868356+00:00, execution_date=20240607T100402, start_date=20240607T100413, end_date=20240607T100413
[2024-06-07T10:04:13.506+0000] {standard_task_runner.py:110} ERROR - Failed to execute job 573 for task insert_new_row (relation "table_name" does not exist
LINE 1: INSERT INTO table_name VALUES(11, 'default', '2024-06-07T10:...
                    ^
; 13112)
[2024-06-07T10:04:13.537+0000] {local_task_job_runner.py:240} INFO - Task exited with return code 1
[2024-06-07T10:04:13.567+0000] {taskinstance.py:3498} INFO - 0 downstream tasks scheduled from follow-on schedule check
[2024-06-07T10:04:13.573+0000] {local_task_job_runner.py:222} INFO - ::endgroup::
