[2024-06-05T12:06:21.750+0000] {local_task_job_runner.py:120} INFO - ::group::Pre task execution logs
[2024-06-05T12:06:21.788+0000] {taskinstance.py:2076} INFO - Dependencies all met for dep_context=non-requeueable deps ti=<TaskInstance: trigger_dag_id.task_troup.dag_1_task_sensor manual__2024-06-05T12:06:13.064083+00:00 [queued]>
[2024-06-05T12:06:21.800+0000] {taskinstance.py:2076} INFO - Dependencies all met for dep_context=requeueable deps ti=<TaskInstance: trigger_dag_id.task_troup.dag_1_task_sensor manual__2024-06-05T12:06:13.064083+00:00 [queued]>
[2024-06-05T12:06:21.801+0000] {taskinstance.py:2306} INFO - Starting attempt 1 of 1
[2024-06-05T12:06:21.824+0000] {taskinstance.py:2330} INFO - Executing <Task(ExternalTaskSensor): task_troup.dag_1_task_sensor> on 2024-06-05 12:06:13.064083+00:00
[2024-06-05T12:06:21.839+0000] {warnings.py:110} WARNING - /home/***/.local/lib/python3.12/site-packages/***/task/task_runner/standard_task_runner.py:61: DeprecationWarning: This process (pid=3903) is multi-threaded, use of fork() may lead to deadlocks in the child.
  pid = os.fork()

[2024-06-05T12:06:21.841+0000] {standard_task_runner.py:63} INFO - Started process 3914 to run task
[2024-06-05T12:06:21.841+0000] {standard_task_runner.py:90} INFO - Running: ['***', 'tasks', 'run', 'trigger_dag_id', 'task_troup.dag_1_task_sensor', 'manual__2024-06-05T12:06:13.064083+00:00', '--job-id', '483', '--raw', '--subdir', 'DAGS_FOLDER/trigger_dag.py', '--cfg-path', '/tmp/tmpkf1r4hvx']
[2024-06-05T12:06:21.845+0000] {standard_task_runner.py:91} INFO - Job 483: Subtask task_troup.dag_1_task_sensor
[2024-06-05T12:06:21.917+0000] {task_command.py:426} INFO - Running <TaskInstance: trigger_dag_id.task_troup.dag_1_task_sensor manual__2024-06-05T12:06:13.064083+00:00 [running]> on host db8c7b709f57
[2024-06-05T12:06:22.049+0000] {taskinstance.py:2648} INFO - Exporting env vars: AIRFLOW_CTX_DAG_OWNER='***' AIRFLOW_CTX_DAG_ID='trigger_dag_id' AIRFLOW_CTX_TASK_ID='task_troup.dag_1_task_sensor' AIRFLOW_CTX_EXECUTION_DATE='2024-06-05T12:06:13.064083+00:00' AIRFLOW_CTX_TRY_NUMBER='1' AIRFLOW_CTX_DAG_RUN_ID='manual__2024-06-05T12:06:13.064083+00:00'
[2024-06-05T12:06:22.053+0000] {taskinstance.py:430} INFO - ::endgroup::
[2024-06-05T12:06:22.054+0000] {baseoperator.py:399} WARNING - ExternalTaskSensor.execute cannot be called outside TaskInstance!
[2024-06-05T12:06:22.070+0000] {taskinstance.py:441} INFO - ::group::Post task execution logs
[2024-06-05T12:06:22.074+0000] {taskinstance.py:2905} ERROR - Task failed with exception
Traceback (most recent call last):
  File "/home/airflow/.local/lib/python3.12/site-packages/airflow/models/taskinstance.py", line 465, in _execute_task
    result = _execute_callable(context=context, **execute_callable_kwargs)
             ^^^^^^^^^^^^^^^^^^^^^^^^^^^^^^^^^^^^^^^^^^^^^^^^^^^^^^^^^^^^^
  File "/home/airflow/.local/lib/python3.12/site-packages/airflow/models/taskinstance.py", line 432, in _execute_callable
    return execute_callable(context=context, **execute_callable_kwargs)
           ^^^^^^^^^^^^^^^^^^^^^^^^^^^^^^^^^^^^^^^^^^^^^^^^^^^^^^^^^^^^
  File "/home/airflow/.local/lib/python3.12/site-packages/airflow/models/baseoperator.py", line 400, in wrapper
    return func(self, *args, **kwargs)
           ^^^^^^^^^^^^^^^^^^^^^^^^^^^
  File "/home/airflow/.local/lib/python3.12/site-packages/airflow/sensors/external_task.py", line 348, in execute
    super().execute(context)
  File "/home/airflow/.local/lib/python3.12/site-packages/airflow/models/baseoperator.py", line 400, in wrapper
    return func(self, *args, **kwargs)
           ^^^^^^^^^^^^^^^^^^^^^^^^^^^
  File "/home/airflow/.local/lib/python3.12/site-packages/airflow/sensors/base.py", line 264, in execute
    raise e
  File "/home/airflow/.local/lib/python3.12/site-packages/airflow/sensors/base.py", line 246, in execute
    poke_return = self.poke(context)
                  ^^^^^^^^^^^^^^^^^^
  File "/home/airflow/.local/lib/python3.12/site-packages/airflow/utils/session.py", line 79, in wrapper
    return func(*args, session=session, **kwargs)
           ^^^^^^^^^^^^^^^^^^^^^^^^^^^^^^^^^^^^^^
  File "/home/airflow/.local/lib/python3.12/site-packages/airflow/sensors/external_task.py", line 254, in poke
    dttm_filter = self._get_dttm_filter(context)
                  ^^^^^^^^^^^^^^^^^^^^^^^^^^^^^^
  File "/home/airflow/.local/lib/python3.12/site-packages/airflow/sensors/external_task.py", line 243, in _get_dttm_filter
    dttm = self._handle_execution_date_fn(context=context)
           ^^^^^^^^^^^^^^^^^^^^^^^^^^^^^^^^^^^^^^^^^^^^^^^
  File "/home/airflow/.local/lib/python3.12/site-packages/airflow/sensors/external_task.py", line 455, in _handle_execution_date_fn
    return kwargs_callable(logical_date, **kwargs)
           ^^^^^^^^^^^^^^^^^^^^^^^^^^^^^^^^^^^^^^^
  File "/home/airflow/.local/lib/python3.12/site-packages/airflow/utils/operator_helpers.py", line 212, in kwargs_func
    return func(*args, **kwargs)
           ^^^^^^^^^^^^^^^^^^^^^
  File "/opt/airflow/dags/trigger_dag.py", line 25, in get_execution_date
    execution_date = datetime.strptime(execution_date_str, '%Y-%m-%d %H:%M:%S.%f%z')
                     ^^^^^^^^^^^^^^^^^^^^^^^^^^^^^^^^^^^^^^^^^^^^^^^^^^^^^^^^^^^^^^^
TypeError: strptime() argument 1 must be str, not None
[2024-06-05T12:06:22.092+0000] {taskinstance.py:1206} INFO - Marking task as FAILED. dag_id=trigger_dag_id, task_id=task_troup.dag_1_task_sensor, run_id=manual__2024-06-05T12:06:13.064083+00:00, execution_date=20240605T120613, start_date=20240605T120621, end_date=20240605T120622
[2024-06-05T12:06:22.112+0000] {standard_task_runner.py:110} ERROR - Failed to execute job 483 for task task_troup.dag_1_task_sensor (strptime() argument 1 must be str, not None; 3914)
[2024-06-05T12:06:22.149+0000] {local_task_job_runner.py:240} INFO - Task exited with return code 1
[2024-06-05T12:06:22.199+0000] {taskinstance.py:3498} INFO - 0 downstream tasks scheduled from follow-on schedule check
[2024-06-05T12:06:22.205+0000] {local_task_job_runner.py:222} INFO - ::endgroup::
